Workbook

Sheet V1
A1: Session: untitled
A2: Training Data: Excel_MultiModal_Dataset1 Observations: 10820
A3: Predictors: 10 Predictor Names: body_temperature, sleep_quality, muscle_activity, step_count, ground_reaction_force, altitude, training_load, fatigue_index, sport_type, age
A4: Response Name: injury_occurred Response Classes: 2 Response Class Names: 0, 1
A5: Validation: 5-fold cross-validation
A6: Test Data: Excel_MultiModal_Dataset1 Observations: 1909
A9: Favorite | B9: Model Number | C9: Status | D9: Model Type | E9: Accuracy % (Validation) | F9: Total Cost (Validation) | G9: Error Rate % (Validation) | H9: Macro Precision % (Validation) | I9: Micro Precision % (Validation) | J9: Weighted Precision % (Validation) | K9: Macro Recall % (Validation) | L9: Micro Recall % (Validation) | M9: Weighted Recall % (Validation) | N9: Macro F1 Score % (Validation) | O9: Micro F1 Score % (Validation) | P9: Weighted F1 Score % (Validation) | Q9: Accuracy % (Test) | R9: Total Cost (Test) | S9: Error Rate % (Test) | T9: Macro Precision % (Test) | U9: Micro Precision % (Test) | V9: Weighted Precision % (Test) | W9: Macro Recall % (Test) | X9: Micro Recall % (Test) | Y9: Weighted Recall % (Test) | Z9: Macro F1 Score % (Test) | AA9: Micro F1 Score % (Test) | AB9: Weighted F1 Score % (Test) | AC9: Prediction Speed (obs/sec) | AD9: Training Time (sec) | AE9: Compact Model Size (bytes) | AF9: Coder Model Size (bytes) | AG9: Hyperparameters | AH9: Selected Features | AI9: Feature Ranking Algorithm | AJ9: PCA | AK9: Costs | AL9: Optimizer Options
A10: 0 | B10: 2.1 | C10: Tested | D10: Tree | E10: 85.101664 | F10: 1612 | G10: 14.898336 | H10: 68.839286 | I10: 85.101664 | J10: 82.065091 | K10: 59.467304 | L10: 85.101664 | M10: 85.101664 | N10: 61.552529 | O10: 85.101664 | P10: 82.67667 | Q10: 85.070718 | R10: 285 | S10: 14.929282 | T10: 68.674643 | U10: 85.070718 | V10: 82.056953 | W10: 59.55818 | X10: 85.070718 | Y10: 85.070718 | Z10: 61.637394 | AA10: 85.070718 | AB10: 82.699115 | AC10: 646510.52 | AD10: 3.436916 | AE10: 31503 | AF10: 21654 | AG10: Maximum number of splits: 100; Split criterion: Gini's diversity index; Surrogate decision splits: Off | AH10: 46305 | AI10: None | AJ10: Disabled | AK10: Default | AL10: Not applicable
A11: 0 | B11: 2.1 | C11: Tested | D11: SVM | E11: 85.101664 | F11: 1612 | G11: 14.898336 | H11: NaN | I11: 85.101664 | J11: NaN | K11: 50 | L11: 85.101664 | M11: 85.101664 | N11: 45.975634 | O11: 85.101664 | P11: 78.252059 | Q11: 85.123101 | R11: 284 | S11: 14.876899 | T11: NaN | U11: 85.123101 | V11: NaN | W11: 50 | X11: 85.123101 | Y11: 85.123101 | Z11: 45.98189 | AA11: 85.123101 | AB11: 78.282422 | AC11: 13464.075 | AD11: 66.544574 | AE11: 510603 | AF11: 508610 | AG11: Kernel function: Quadratic; Kernel scale: Automatic; Box constraint level: 1; Multiclass coding: One-vs-One; Standardize data: Yes | AH11: 46305 | AI11: None | AJ11: Disabled | AK11: Default | AL11: Not applicable
A12: 0 | B12: 2.11 | C12: Tested | D12: SVM | E12: 85.536044 | F12: 1565 | G12: 14.463956 | H12: 75.496726 | I12: 85.536044 | J12: 82.752545 | K12: 52.839531 | L12: 85.536044 | M12: 85.536044 | N12: 51.7784 | O12: 85.536044 | P12: 80.103051 | Q12: 85.646936 | R12: 274 | S12: 14.353064 | T12: 76.30832 | U12: 85.646936 | V12: 83.081215 | W12: 53.213434 | X12: 85.646936 | Y12: 85.646936 | Z12: 52.459609 | AA12: 85.646936 | AB12: 80.361932 | AC12: 273598.5 | AD12: 583.3004 | AE12: 445203 | AF12: 443210 | AG12: Kernel function: Cubic; Kernel scale: Automatic; Box constraint level: 1; Multiclass coding: One-vs-One; Standardize data: Yes | AH12: 46305 | AI12: None | AJ12: Disabled | AK12: Default | AL12: Not applicable
A13: 0 | B13: 2.12 | C13: Tested | D13: SVM | E13: 85.101664 | F13: 1612 | G13: 14.898336 | H13: NaN | I13: 85.101664 | J13: NaN | K13: 50 | L13: 85.101664 | M13: 85.101664 | N13: 45.975634 | O13: 85.101664 | P13: 78.252059 | Q13: 85.123101 | R13: 284 | S13: 14.876899 | T13: NaN | U13: 85.123101 | V13: NaN | W13: 50 | X13: 85.123101 | Y13: 85.123101 | Z13: 45.98189 | AA13: 85.123101 | AB13: 78.282422 | AC13: 4724.5195 | AD13: 44.586241 | AE13: 1298639 | AF13: 1296650 | AG13: Kernel function: Gaussian; Kernel scale: 0.79; Box constraint level: 1; Multiclass coding: One-vs-One; Standardize data: Yes | AH13: 46305 | AI13: None | AJ13: Disabled | AK13: Default | AL13: Not applicable
A14: 0 | B14: 2.13 | C14: Tested | D14: SVM | E14: 85.38817 | F14: 1581 | G14: 14.61183 | H14: 75.93645 | I14: 85.38817 | J14: 82.690473 | K14: 51.780332 | L14: 85.38817 | M14: 85.38817 | N14: 49.7249 | O14: 85.38817 | P14: 79.451466 | Q14: 85.437402 | R14: 278 | S14: 14.562598 | T14: 73.652927 | U14: 85.437402 | V14: 82.162879 | W14: 52.509209 | X14: 85.437402 | Y14: 85.437402 | Z14: 51.198919 | AA14: 85.437402 | AB14: 79.912994 | AC14: 7379.6661 | AD14: 39.690313 | AE14: 492959 | AF14: 490970 | AG14: Kernel function: Gaussian; Kernel scale: 3.2; Box constraint level: 1; Multiclass coding: One-vs-One; Standardize data: Yes | AH14: 46305 | AI14: None | AJ14: Disabled | AK14: Default | AL14: Not applicable
A15: 0 | B15: 2.14 | C15: Tested | D15: SVM | E15: 85.101664 | F15: 1612 | G15: 14.898336 | H15: NaN | I15: 85.101664 | J15: NaN | K15: 50 | L15: 85.101664 | M15: 85.101664 | N15: 45.975634 | O15: 85.101664 | P15: 78.252059 | Q15: 85.123101 | R15: 284 | S15: 14.876899 | T15: NaN | U15: 85.123101 | V15: NaN | W15: 50 | X15: 85.123101 | Y15: 85.123101 | Z15: 45.98189 | AA15: 85.123101 | AB15: 78.282422 | AC15: 7552.7646 | AD15: 34.58756 | AE15: 451079 | AF15: 449090 | AG15: Kernel function: Gaussian; Kernel scale: 13; Box constraint level: 1; Multiclass coding: One-vs-One; Standardize data: Yes | AH15: 46305 | AI15: None | AJ15: Disabled | AK15: Default | AL15: Not applicable
A16: 0 | B16: 2.15 | C16: Tested | D16: Ensemble | E16: 86.090573 | F16: 1505 | G16: 13.909427 | H16: 74.98137 | I16: 86.090573 | J16: 83.424987 | K16: 57.233717 | L16: 86.090573 | M16: 86.090573 | N16: 59.003156 | O16: 86.090573 | P16: 82.397814 | Q16: 86.380304 | R16: 260 | S16: 13.619696 | T16: 77.870935 | U16: 86.380304 | V16: 84.278045 | W16: 57.131094 | X16: 86.380304 | Y16: 86.380304 | Z16: 58.89728 | AA16: 86.380304 | AB16: 82.506976 | AC16: 26964.119 | AD16: 15.428371 | AE16: 311092 | AF16: 138569 | AG16: Ensemble method: AdaBoost; Learner type: Decision tree; Maximum number of splits: 20; Number of learners: 30; Learning rate: 0.1; Number of predictors to sample: Select All | AH16: 46305 | AI16: None | AJ16: Disabled | AK16: Default | AL16: Not applicable
A17: 0 | B17: 2.16 | C17: Tested | D17: Ensemble | E17: 85.720887 | F17: 1545 | G17: 14.279113 | H17: 71.618927 | I17: 85.720887 | J17: 82.69175 | K17: 58.551753 | L17: 85.720887 | M17: 85.720887 | N17: 60.674607 | O17: 85.720887 | P17: 82.707212 | Q17: 85.751702 | R17: 272 | S17: 14.248298 | T17: 71.451238 | U17: 85.751702 | V17: 82.886493 | W17: 59.667606 | X17: 85.751702 | Y17: 85.751702 | Z17: 62.021065 | AA17: 85.751702 | AB17: 83.109723 | AC17: 15918.998 | AD17: 29.764373 | AE17: 6806304 | AF17: 4919309 | AG17: Ensemble method: Bag; Learner type: Decision tree; Maximum number of splits: 10819; Number of learners: 30; Number of predictors to sample: Select All | AH17: 46305 | AI17: None | AJ17: Disabled | AK17: Default | AL17: Not applicable
A18: 0 | B18: 2.17 | C18: Tested | D18: Ensemble | E18: 71.367837 | F18: 3098 | G18: 28.632163 | H18: 62.480446 | I18: 71.367837 | J18: 84.658049 | K18: 72.661288 | L18: 71.367837 | M18: 71.367837 | N18: 62.23909 | O18: 71.367837 | P18: 75.273294 | Q18: 69.722368 | R18: 578 | S18: 30.277632 | T18: 62.262972 | U18: 69.722368 | V18: 84.945625 | W18: 72.91701 | X18: 69.722368 | Y18: 69.722368 | Z18: 61.289573 | AA18: 69.722368 | AB18: 73.981355 | AC18: 32026.237 | AD18: 13.692485 | AE18: 294824 | AF18: 115517 | AG18: Ensemble method: RUSBoost; Learner type: Decision tree; Maximum number of splits: 20; Number of learners: 30; Learning rate: 0.1; Number of predictors to sample: Select All | AH18: 46305 | AI18: None | AJ18: Disabled | AK18: Default | AL18: Not applicable
A19: 0 | B19: 2.18 | C19: Tested | D19: Neural Network | E19: 85.443623 | F19: 1575 | G19: 14.556377 | H19: 70.477262 | I19: 85.443623 | J19: 81.92124 | K19: 56.341866 | L19: 85.443623 | M19: 85.443623 | N19: 57.657898 | O19: 85.443623 | P19: 81.737803 | Q19: 85.280251 | R19: 281 | S19: 14.719749 | T19: 69.304491 | U19: 85.280251 | V19: 81.595653 | W19: 56.339653 | X19: 85.280251 | Y19: 85.280251 | Z19: 57.645338 | AA19: 85.280251 | AB19: 81.678035 | AC19: 55981.54 | AD19: 37.813289 | AE19: 8084 | AF19: 5630 | AG19: Number of fully connected layers: 1; First layer size: 10; Activation: ReLU; Iteration limit: 1000; Regularization strength (Lambda): 0; Standardize data: Yes | AH19: 46305 | AI19: None | AJ19: Disabled | AK19: Default | AL19: Not applicable
A20: 0 | B20: 2.19 | C20: Tested | D20: Neural Network | E20: 84.787431 | F20: 1646 | G20: 15.212569 | H20: 67.242602 | I20: 84.787431 | J20: 81.212258 | K20: 57.568333 | L20: 84.787431 | M20: 84.787431 | N20: 59.209813 | O20: 84.787431 | P20: 81.885768 | Q20: 84.337349 | R20: 299 | S20: 15.662651 | T20: 64.891554 | U20: 84.337349 | V20: 80.276104 | W20: 56.221668 | X20: 84.337349 | Y20: 84.337349 | Z20: 57.40229 | AA20: 84.337349 | AB20: 81.1967 | AC20: 422970.17 | AD20: 63.722263 | AE20: 10004 | AF20: 7550 | AG20: Number of fully connected layers: 1; First layer size: 25; Activation: ReLU; Iteration limit: 1000; Regularization strength (Lambda): 0; Standardize data: Yes | AH20: 46305 | AI20: None | AJ20: Disabled | AK20: Default | AL20: Not applicable
A21: 0 | B21: 2.2 | C21: Tested | D21: Tree | E21: 85.711645 | F21: 1546 | G21: 14.288355 | H21: 72.151026 | I21: 85.711645 | J21: 82.530557 | K21: 56.934322 | L21: 85.711645 | M21: 85.711645 | N21: 58.527822 | O21: 85.711645 | P21: 82.099548 | Q21: 85.751702 | R21: 272 | S21: 14.248298 | T21: 72.319666 | U21: 85.751702 | V21: 82.594829 | W21: 56.907151 | X21: 85.751702 | Y21: 85.751702 | Z21: 58.495754 | AA21: 85.751702 | AB21: 82.122274 | AC21: 718364.1 | AD21: 2.592996 | AE21: 9683 | AF21: 5114 | AG21: Maximum number of splits: 20; Split criterion: Gini's diversity index; Surrogate decision splits: Off | AH21: 46305 | AI21: None | AJ21: Disabled | AK21: Default | AL21: Not applicable
A22: 0 | B22: 2.2 | C22: Tested | D22: Neural Network | E22: 79.537893 | F22: 2214 | G22: 20.462107 | H22: 58.762136 | I22: 79.537893 | J22: 78.963448 | K22: 58.27098 | L22: 79.537893 | M22: 79.537893 | N22: 58.497653 | O22: 79.537893 | P22: 79.242936 | Q22: 79.93714 | R22: 383 | S22: 20.06286 | T22: 58.557815 | U22: 79.93714 | V22: 78.761955 | W22: 57.559805 | X22: 79.93714 | Y22: 79.93714 | Z22: 57.977183 | AA22: 79.93714 | AB22: 79.316532 | AC22: 490881.05 | AD22: 109.0128 | AE22: 19604 | AF22: 17150 | AG22: Number of fully connected layers: 1; First layer size: 100; Activation: ReLU; Iteration limit: 1000; Regularization strength (Lambda): 0; Standardize data: Yes | AH22: 46305 | AI22: None | AJ22: Disabled | AK22: Default | AL22: Not applicable
A23: 0 | B23: 2.21 | C23: Tested | D23: Neural Network | E23: 84.916821 | F23: 1632 | G23: 15.083179 | H23: 67.448497 | I23: 84.916821 | J23: 81.032587 | K23: 56.364988 | L23: 84.916821 | M23: 84.916821 | N23: 57.649303 | O23: 84.916821 | P23: 81.506025 | Q23: 85.332635 | R23: 280 | S23: 14.667365 | T23: 69.615134 | U23: 85.332635 | V23: 81.721492 | W23: 56.51571 | X23: 85.332635 | Y23: 85.332635 | Z23: 57.898551 | AA23: 85.332635 | AB23: 81.772079 | AC23: 349099.83 | AD23: 63.148026 | AE23: 9856 | AF23: 6878 | AG23: Number of fully connected layers: 2; First layer size: 10; Second layer size: 10; Activation: ReLU; Iteration limit: 1000; Regularization strength (Lambda): 0; Standardize data: Yes | AH23: 46305 | AI23: None | AJ23: Disabled | AK23: Default | AL23: Not applicable
A24: 0 | B24: 2.22 | C24: Tested | D24: Neural Network | E24: 84.205176 | F24: 1709 | G24: 15.794824 | H24: 64.680616 | I24: 84.205176 | J24: 80.249433 | K24: 56.509794 | L24: 84.205176 | M24: 84.205176 | N24: 57.764571 | O24: 84.205176 | P24: 81.224778 | Q24: 84.65165 | R24: 293 | S24: 15.34835 | T24: 65.34862 | U24: 84.65165 | V24: 80.131809 | W24: 54.808126 | X24: 84.65165 | Y24: 84.65165 | Z24: 55.401642 | AA24: 84.65165 | AB24: 80.773091 | AC24: 367839.54 | AD24: 76.6924 | AE24: 11628 | AF24: 8126 | AG24: Number of fully connected layers: 3; First layer size: 10; Second layer size: 10; Third layer size: 10; Activation: ReLU; Iteration limit: 1000; Regularization strength (Lambda): 0; Standardize data: Yes | AH24: 46305 | AI24: None | AJ24: Disabled | AK24: Default | AL24: Not applicable
A25: 0 | B25: 2.23 | C25: Tested | D25: Kernel | E25: 85.101664 | F25: 1612 | G25: 14.898336 | H25: NaN | I25: 85.101664 | J25: NaN | K25: 50 | L25: 85.101664 | M25: 85.101664 | N25: 45.975634 | O25: 85.101664 | P25: 78.252059 | Q25: 85.123101 | R25: 284 | S25: 14.876899 | T25: NaN | U25: 85.123101 | V25: NaN | W25: 50 | X25: 85.123101 | Y25: 85.123101 | Z25: 45.98189 | AA25: 85.123101 | AB25: 78.282422 | AC25: 72001.81 | AD25: 39.316543 | AE25: 13438 | AF25: 14120 | AG25: Learner: SVM; Number of expansion dimensions: Auto; Regularization strength (Lambda): Auto; Kernel scale: Auto; Multiclass coding: One-vs-One; Standardize data: Yes; Iteration limit: 1000 | AH25: 46305 | AI25: None | AJ25: Disabled | AK25: Default | AL25: Not applicable
A26: 0 | B26: 2.24 | C26: Tested | D26: Kernel | E26: 85.295749 | F26: 1591 | G26: 14.704251 | H26: 73.644194 | I26: 85.295749 | J26: 81.960789 | K26: 51.521333 | L26: 85.295749 | M26: 85.295749 | N26: 49.243724 | O26: 85.295749 | P26: 79.274558 | Q26: 85.123101 | R26: 284 | S26: 14.876899 | T26: 67.747485 | U26: 85.123101 | V26: 80.21442 | W26: 51.452871 | X26: 85.123101 | Y26: 85.123101 | Z26: 49.248495 | AA26: 85.123101 | AB26: 79.222231 | AC26: 76469.133 | AD26: 62.469819 | AE26: 13480 | AF26: 14120 | AG26: Learner: Logistic Regression; Number of expansion dimensions: Auto; Regularization strength (Lambda): Auto; Kernel scale: Auto; Multiclass coding: One-vs-One; Standardize data: Yes; Iteration limit: 1000 | AH26: 46305 | AI26: None | AJ26: Disabled | AK26: Default | AL26: Not applicable
A27: 0 | B27: 2.3 | C27: Tested | D27: Tree | E27: 85.147874 | F27: 1607 | G27: 14.852126 | H27: 92.570504 | I27: 85.147874 | J27: 87.35475 | K27: 50.155087 | L27: 85.147874 | M27: 85.147874 | N27: 46.296329 | O27: 85.147874 | P27: 78.363735 | Q27: 85.123101 | R27: 284 | S27: 14.876899 | T27: NaN | U27: 85.123101 | V27: NaN | W27: 50 | X27: 85.123101 | Y27: 85.123101 | Z27: 45.98189 | AA27: 85.123101 | AB27: 78.282422 | AC27: 730045.21 | AD27: 0.887745 | AE27: 5063 | AF27: 3374 | AG27: Maximum number of splits: 4; Split criterion: Gini's diversity index; Surrogate decision splits: Off | AH27: 46305 | AI27: None | AJ27: Disabled | AK27: Default | AL27: Not applicable
A28: 0 | B28: 2.4 | C28: Tested | D28: Binary GLM Logistic Regression | E28: 85.674677 | F28: 1550 | G28: 14.325323 | H28: 72.296757 | I28: 85.674677 | J28: 82.42621 | K28: 56.17057 | L28: 85.674677 | M28: 85.674677 | N28: 57.418668 | O28: 85.674677 | P28: 81.77 | Q28: 86.066003 | R28: 266 | S28: 13.933997 | T28: 74.903286 | U28: 86.066003 | V28: 83.365244 | W28: 56.946479 | X28: 86.066003 | Y28: 86.066003 | Z28: 58.589887 | AA28: 86.066003 | AB28: 82.284724 | AC28: 179665.58 | AD28: 2.473797 | AE28: 2486822 | AF28: 6001 | AG28: None | AH28: 46305 | AI28: None | AJ28: Disabled | AK28: Default | AL28: Not applicable
A29: 0 | B29: 2.5 | C29: Tested | D29: Efficient Logistic Regression | E29: 85.101664 | F29: 1612 | G29: 14.898336 | H29: NaN | I29: 85.101664 | J29: NaN | K29: 50 | L29: 85.101664 | M29: 85.101664 | N29: 45.975634 | O29: 85.101664 | P29: 78.252059 | Q29: 85.123101 | R29: 284 | S29: 14.876899 | T29: NaN | U29: 85.123101 | V29: NaN | W29: 50 | X29: 85.123101 | Y29: 85.123101 | Z29: 45.98189 | AA29: 85.123101 | AB29: 78.282422 | AC29: 667159.95 | AD29: 0.947314 | AE29: 11632 | AF29: 3496 | AG29: Learner: Logistic regression; Solver: Auto; Regularization: Auto; Regularization strength (Lambda): Auto; Relative coefficient tolerance (Beta tolerance): 0.0001; Multiclass coding: One-vs-One | AH29: 46305 | AI29: None | AJ29: Disabled | AK29: Default | AL29: Not applicable
A30: 0 | B30: 2.6 | C30: Tested | D30: Efficient Linear SVM | E30: 85.101664 | F30: 1612 | G30: 14.898336 | H30: NaN | I30: 85.101664 | J30: NaN | K30: 50 | L30: 85.101664 | M30: 85.101664 | N30: 45.975634 | O30: 85.101664 | P30: 78.252059 | Q30: 85.123101 | R30: 284 | S30: 14.876899 | T30: NaN | U30: 85.123101 | V30: NaN | W30: 50 | X30: 85.123101 | Y30: 85.123101 | Z30: 45.98189 | AA30: 85.123101 | AB30: 78.282422 | AC30: 675279.29 | AD30: 1.60612 | AE30: 11590 | AF30: 3496 | AG30: Learner: SVM; Solver: Auto; Regularization: Auto; Regularization strength (Lambda): Auto; Relative coefficient tolerance (Beta tolerance): 0.0001; Multiclass coding: One-vs-One | AH30: 46305 | AI30: None | AJ30: Disabled | AK30: Default | AL30: Not applicable
A31: 0 | B31: 2.7 | C31: Tested | D31: Naive Bayes | E31: 83.585952 | F31: 1776 | G31: 16.414048 | H31: 64.916015 | I31: 83.585952 | J31: 81.053571 | K31: 60.009664 | L31: 83.585952 | M31: 83.585952 | N31: 61.539311 | O31: 83.585952 | P31: 81.981973 | Q31: 83.813515 | R31: 309 | S31: 16.186485 | T31: 65.586313 | U31: 83.813515 | V31: 81.386363 | W31: 60.563164 | X31: 83.813515 | Y31: 83.813515 | Z31: 62.16638 | AA31: 83.813515 | AB31: 82.269433 | AC31: 445340.8 | AD31: 0.966749 | AE31: 8976 | AF31: 7327 | AG31: Distribution name for numeric predictors: Gaussian; Distribution name for categorical predictors: MVMN | AH31: 46305 | AI31: None | AJ31: Disabled | AK31: Default | AL31: Not applicable
A32: 0 | B32: 2.8 | C32: Tested | D32: Naive Bayes | E32: 83.909427 | F32: 1741 | G32: 16.090573 | H32: 65.011153 | I32: 83.909427 | J32: 80.796428 | K32: 58.690065 | L32: 83.909427 | M32: 83.909427 | N32: 60.286149 | O32: 83.909427 | P32: 81.789135 | Q32: 84.180199 | R32: 302 | S32: 15.819801 | T32: 65.98304 | U32: 84.180199 | V32: 81.263184 | W32: 59.470964 | X32: 84.180199 | Y32: 84.180199 | Z32: 61.211718 | AA32: 84.180199 | AB32: 82.178861 | AC32: 1040.633 | AD32: 48.199102 | AE32: 3155968 | AF32: 1565693 | AG32: Distribution name for numeric predictors: Kernel; Distribution name for categorical predictors: MVMN; Kernel type: Gaussian; Support: Unbounded; Standardize data: Yes | AH32: 46305 | AI32: None | AJ32: Disabled | AK32: Default | AL32: Not applicable
A33: 0 | B33: 2.9 | C33: Tested | D33: SVM | E33: 85.101664 | F33: 1612 | G33: 14.898336 | H33: NaN | I33: 85.101664 | J33: NaN | K33: 50 | L33: 85.101664 | M33: 85.101664 | N33: 45.975634 | O33: 85.101664 | P33: 78.252059 | Q33: 85.123101 | R33: 284 | S33: 14.876899 | T33: NaN | U33: 85.123101 | V33: NaN | W33: 50 | X33: 85.123101 | Y33: 85.123101 | Z33: 45.98189 | AA33: 85.123101 | AB33: 78.282422 | AC33: 114206.1 | AD33: 8.175629 | AE33: 403179 | AF33: 401090 | AG33: Kernel function: Linear; Kernel scale: Automatic; Box constraint level: 1; Multiclass coding: One-vs-One; Standardize data: Yes | AH33: 46305 | AI33: None | AJ33: Disabled | AK33: Default | AL33: Not applicable

Sheet V2
A1: Session: untitled
A2: Training Data: Excel_MultiModal_Dataset1 Observations: 10820
A3: Predictors: 10 Predictor Names: body_temperature, sleep_quality, muscle_activity, step_count, ground_reaction_force, altitude, training_load, fatigue_index, sport_type, age
A4: Response Name: injury_occurred Response Classes: 2 Response Class Names: 0, 1
A5: Validation: 5-fold cross-validation
A6: Test Data: Excel_MultiModal_Dataset1 Observations: 1909
A9: Favorite | B9: Model Number | C9: Model Type | D9: Status | E9: Accuracy % (Validation) | F9: Total Cost (Validation) | G9: Accuracy % (Test) | H9: Total Cost (Test) | I9: Preset | J9: Error Rate % (Validation) | K9: Macro Precision % (Validation) | L9: Micro Precision % (Validation) | M9: Weighted Precision % (Validation) | N9: Macro Recall % (Validation) | O9: Micro Recall % (Validation) | P9: Weighted Recall % (Validation) | Q9: Macro F1 Score % (Validation) | R9: Micro F1 Score % (Validation) | S9: Weighted F1 Score % (Validation) | T9: Error Rate % (Test) | U9: Macro Precision % (Test) | V9: Micro Precision % (Test) | W9: Weighted Precision % (Test) | X9: Macro Recall % (Test) | Y9: Micro Recall % (Test) | Z9: Weighted Recall % (Test) | AA9: Macro F1 Score % (Test) | AB9: Micro F1 Score % (Test) | AC9: Weighted F1 Score % (Test) | AD9: Prediction Speed (obs/sec) | AE9: Training Time (sec) | AF9: Compact Model Size (bytes) | AG9: Coder Model Size (bytes) | AH9: Hyperparameters | AI9: Selected Features | AJ9: Feature Ranking Algorithm | AK9: PCA | AL9: Costs | AM9: Optimizer Options
A10: 0 | B10: 2.1 | C10: Tree | D10: Tested | E10: 84.593346 | F10: 1667 | G10: 85.280251 | H10: 281 | I10: Fine Tree | J10: 15.406654 | K10: 67.002155 | L10: 84.593346 | M10: 81.422907 | N10: 58.938365 | O10: 84.593346 | P10: 84.593346 | Q10: 60.78128 | R10: 84.593346 | S10: 82.235016 | T10: 14.719749 | U10: 69.470157 | V10: 85.280251 | W10: 82.342857 | X10: 59.826544 | Y10: 85.280251 | Z10: 85.280251 | AA10: 62.015868 | AB10: 85.280251 | AC10: 82.897754 | AD10: 791051.32 | AE10: 3.739183 | AF10: 32299 | AG10: 22290 | AH10: Maximum number of splits: 100; Split criterion: Gini's diversity index; Surrogate decision splits: Off | AI10: 46305 | AJ10: None | AK10: Disabled | AL10: Default | AM10: Not applicable
A11: 0 | B11: 2.1 | C11: SVM | D11: Tested | E11: 85.101664 | F11: 1612 | G11: 85.123101 | H11: 284 | I11: Quadratic SVM | J11: 14.898336 | K11: NaN | L11: 85.101664 | M11: NaN | N11: 50 | O11: 85.101664 | P11: 85.101664 | Q11: 45.975634 | R11: 85.101664 | S11: 78.252059 | T11: 14.876899 | U11: NaN | V11: 85.123101 | W11: NaN | X11: 50 | Y11: 85.123101 | Z11: 85.123101 | AA11: 45.98189 | AB11: 85.123101 | AC11: 78.282422 | AD11: 9972.4513 | AE11: 36.307242 | AF11: 531123 | AG11: 529130 | AH11: Kernel function: Quadratic; Kernel scale: Automatic; Box constraint level: 1; Multiclass coding: One-vs-One; Standardize data: Yes | AI11: 46305 | AJ11: None | AK11: Disabled | AL11: Default | AM11: Not applicable
A12: 0 | B12: 2.11 | C12: SVM | D12: Tested | E12: 85.573013 | F12: 1561 | G12: 85.699319 | H12: 273 | I12: Cubic SVM | J12: 14.426987 | K12: 76.701769 | L12: 85.573013 | M12: 83.101196 | N12: 52.784489 | O12: 85.573013 | P12: 85.573013 | Q12: 51.652225 | R12: 85.573013 | S12: 80.082359 | T12: 14.300681 | U12: 77.461482 | V12: 85.699319 | W12: 83.429575 | X12: 53.244204 | Y12: 85.699319 | Z12: 85.699319 | AA12: 52.49534 | AB12: 85.699319 | AC12: 80.394172 | AD12: 311887.47 | AE12: 542.98609 | AF12: 434283 | AG12: 432290 | AH12: Kernel function: Cubic; Kernel scale: Automatic; Box constraint level: 1; Multiclass coding: One-vs-One; Standardize data: Yes | AI12: 46305 | AJ12: None | AK12: Disabled | AL12: Default | AM12: Not applicable
A13: 0 | B13: 2.12 | C13: SVM | D13: Tested | E13: 85.101664 | F13: 1612 | G13: 85.123101 | H13: 284 | I13: Fine Gaussian SVM | J13: 14.898336 | K13: NaN | L13: 85.101664 | M13: NaN | N13: 50 | O13: 85.101664 | P13: 85.101664 | Q13: 45.975634 | R13: 85.101664 | S13: 78.252059 | T13: 14.876899 | U13: NaN | V13: 85.123101 | W13: NaN | X13: 50 | Y13: 85.123101 | Z13: 85.123101 | AA13: 45.98189 | AB13: 85.123101 | AC13: 78.282422 | AD13: 5108.3639 | AE13: 40.691241 | AF13: 1299359 | AG13: 1297370 | AH13: Kernel function: Gaussian; Kernel scale: 0.79; Box constraint level: 1; Multiclass coding: One-vs-One; Standardize data: Yes | AI13: 46305 | AJ13: None | AK13: Disabled | AL13: Default | AM13: Not applicable
A14: 0 | B14: 2.13 | C14: SVM | D14: Tested | E14: 85.425139 | F14: 1577 | G14: 85.437402 | H14: 278 | I14: Medium Gaussian SVM | J14: 14.574861 | K14: 77.832092 | L14: 85.425139 | M14: 83.249787 | N14: 51.750878 | O14: 85.425139 | P14: 85.425139 | Q14: 49.636182 | R14: 85.425139 | S14: 79.441348 | T14: 14.562598 | U14: 74.663969 | V14: 85.437402 | W14: 82.410443 | X14: 52.218635 | Y14: 85.437402 | Z14: 85.437402 | AA14: 50.617305 | AB14: 85.437402 | AC14: 79.746282 | AD14: 6825.4563 | AE14: 38.388437 | AF14: 493199 | AG14: 491210 | AH14: Kernel function: Gaussian; Kernel scale: 3.2; Box constraint level: 1; Multiclass coding: One-vs-One; Standardize data: Yes | AI14: 46305 | AJ14: None | AK14: Disabled | AL14: Default | AM14: Not applicable
A15: 0 | B15: 2.14 | C15: SVM | D15: Tested | E15: 85.101664 | F15: 1612 | G15: 85.123101 | H15: 284 | I15: Coarse Gaussian SVM | J15: 14.898336 | K15: NaN | L15: 85.101664 | M15: NaN | N15: 50 | O15: 85.101664 | P15: 85.101664 | Q15: 45.975634 | R15: 85.101664 | S15: 78.252059 | T15: 14.876899 | U15: NaN | V15: 85.123101 | W15: NaN | X15: 50 | Y15: 85.123101 | Z15: 85.123101 | AA15: 45.98189 | AB15: 85.123101 | AC15: 78.282422 | AD15: 7232.0305 | AE15: 35.861007 | AF15: 462839 | AG15: 460850 | AH15: Kernel function: Gaussian; Kernel scale: 13; Box constraint level: 1; Multiclass coding: One-vs-One; Standardize data: Yes | AI15: 46305 | AJ15: None | AK15: Disabled | AL15: Default | AM15: Not applicable
A16: 0 | B16: 2.15 | C16: Ensemble | D16: Tested | E16: 86.127542 | F16: 1501 | G16: 86.904138 | H16: 250 | I16: Boosted Trees | J16: 13.872458 | K16: 75.01102 | L16: 86.127542 | M16: 83.48734 | N16: 57.51131 | O16: 86.127542 | P16: 86.127542 | Q16: 59.399532 | R16: 86.127542 | S16: 82.525852 | T16: 13.095862 | U16: 79.67133 | V16: 86.904138 | W16: 85.204243 | X16: 59.182232 | Y16: 86.904138 | Z16: 86.904138 | AA16: 61.852715 | AB16: 86.904138 | AC16: 83.568267 | AD16: 42855.049 | AE16: 11.691848 | AF16: 311332 | AG16: 138241 | AH16: Ensemble method: AdaBoost; Learner type: Decision tree; Maximum number of splits: 20; Number of learners: 30; Learning rate: 0.1; Number of predictors to sample: Select All | AI16: 46305 | AJ16: None | AK16: Disabled | AL16: Default | AM16: Not applicable
A17: 0 | B17: 2.16 | C17: Ensemble | D17: Tested | E17: 85.591497 | F17: 1559 | G17: 86.066003 | H17: 266 | I17: Bagged Trees | J17: 14.408503 | K17: 71.031433 | L17: 85.591497 | M17: 82.407513 | N17: 57.989573 | O17: 85.591497 | P17: 85.591497 | Q17: 59.926991 | R17: 85.591497 | S17: 82.44086 | T17: 13.933997 | U17: 72.828 | V17: 86.066003 | W17: 83.413666 | X17: 60.288082 | Y17: 86.066003 | Z17: 86.066003 | AA17: 62.858836 | AB17: 86.066003 | AC17: 83.482303 | AD17: 23982.038 | AE17: 29.570914 | AF17: 6786504 | AG17: 4911469 | AH17: Ensemble method: Bag; Learner type: Decision tree; Maximum number of splits: 10819; Number of learners: 30; Number of predictors to sample: Select All | AI17: 46305 | AJ17: None | AK17: Disabled | AL17: Default | AM17: Not applicable
A18: 0 | B18: 2.17 | C18: Ensemble | D18: Tested | E18: 70.933457 | F18: 3145 | G18: 71.346255 | H18: 547 | I18: RUSBoosted Trees | J18: 29.066543 | K18: 62.445771 | L18: 70.933457 | M18: 84.75458 | N18: 72.789884 | O18: 70.933457 | P18: 70.933457 | Q18: 62.014259 | R18: 70.933457 | S18: 74.936293 | T18: 28.653745 | U18: 62.355408 | V18: 71.346255 | W18: 84.559321 | X18: 72.417985 | Y18: 71.346255 | Z18: 71.346255 | AA18: 62.123524 | AB18: 71.346255 | AC18: 75.252698 | AD18: 79961.571 | AE18: 9.361052 | AF18: 294056 | AG18: 109613 | AH18: Ensemble method: RUSBoost; Learner type: Decision tree; Maximum number of splits: 20; Number of learners: 30; Learning rate: 0.1; Number of predictors to sample: Select All | AI18: 46305 | AJ18: None | AK18: Disabled | AL18: Default | AM18: Not applicable
A19: 0 | B19: 2.18 | C19: Neural Network | D19: Tested | E19: 85.51756 | F19: 1567 | G19: 86.01362 | H19: 267 | I19: Narrow Neural Network | J19: 14.48244 | K19: 71.098993 | L19: 85.51756 | M19: 82.049146 | N19: 56.052672 | O19: 85.51756 | P19: 85.51756 | Q19: 57.238486 | R19: 85.51756 | S19: 81.651243 | T19: 13.98638 | U19: 74.45708 | V19: 86.01362 | W19: 83.227493 | X19: 56.91571 | Y19: 86.01362 | Z19: 86.01362 | AA19: 58.539327 | AB19: 86.01362 | AC19: 82.247838 | AD19: 224607.15 | AE19: 31.290209 | AF19: 8084 | AG19: 5630 | AH19: Number of fully connected layers: 1; First layer size: 10; Activation: ReLU; Iteration limit: 1000; Regularization strength (Lambda): 0; Standardize data: Yes | AI19: 46305 | AJ19: None | AK19: Disabled | AL19: Default | AM19: Not applicable
A20: 0 | B20: 2.19 | C20: Neural Network | D20: Tested | E20: 84.593346 | F20: 1667 | G20: 85.542169 | H20: 276 | I20: Medium Neural Network | J20: 15.406654 | K20: 66.536292 | L20: 84.593346 | M20: 81.013955 | N20: 57.607825 | O20: 84.593346 | P20: 84.593346 | Q20: 59.216595 | R20: 84.593346 | S20: 81.801457 | T20: 14.457831 | U20: 70.591729 | V20: 85.542169 | W20: 82.405836 | X20: 58.527519 | Y20: 85.542169 | Z20: 85.542169 | AA20: 60.589714 | AB20: 85.542169 | AC20: 82.618181 | AD20: 350422.64 | AE20: 44.940085 | AF20: 10004 | AG20: 7550 | AH20: Number of fully connected layers: 1; First layer size: 25; Activation: ReLU; Iteration limit: 1000; Regularization strength (Lambda): 0; Standardize data: Yes | AI20: 46305 | AJ20: None | AK20: Disabled | AL20: Default | AM20: Not applicable
A21: 0 | B21: 2.2 | C21: Tree | D21: Tested | E21: 85.693161 | F21: 1548 | G21: 86.223153 | H21: 263 | I21: Medium Tree | J21: 14.306839 | K21: 71.720204 | L21: 85.693161 | M21: 82.546252 | N21: 57.665494 | O21: 85.693161 | P21: 85.693161 | Q21: 59.525402 | R21: 85.693161 | S21: 82.372562 | T21: 13.776847 | U21: 73.333242 | V21: 86.223153 | W21: 83.727332 | X21: 61.106826 | Y21: 86.223153 | Z21: 86.223153 | AA21: 63.835243 | AB21: 86.223153 | AC21: 83.823384 | AD21: 813717.38 | AE21: 0.787302 | AF21: 9311 | AG21: 4766 | AH21: Maximum number of splits: 20; Split criterion: Gini's diversity index; Surrogate decision splits: Off | AI21: 46305 | AJ21: None | AK21: Disabled | AL21: Default | AM21: Not applicable
A22: 0 | B22: 2.2 | C22: Neural Network | D22: Tested | E22: 80.092421 | F22: 2154 | G22: 80.618125 | H22: 370 | I22: Wide Neural Network | J22: 19.907579 | K22: 59.74215 | L22: 80.092421 | M22: 79.418915 | N22: 59.082942 | O22: 80.092421 | P22: 80.092421 | Q22: 59.38351 | R22: 80.092421 | S22: 79.743967 | T22: 19.381875 | U22: 59.234661 | V22: 80.618125 | W22: 78.969847 | X22: 57.669231 | Y22: 80.618125 | Z22: 80.618125 | AA22: 58.271301 | AB22: 80.618125 | AC22: 79.722332 | AD22: 446277.58 | AE22: 83.706234 | AF22: 19604 | AG22: 17150 | AH22: Number of fully connected layers: 1; First layer size: 100; Activation: ReLU; Iteration limit: 1000; Regularization strength (Lambda): 0; Standardize data: Yes | AI22: 46305 | AJ22: None | AK22: Disabled | AL22: Default | AM22: Not applicable
A23: 0 | B23: 2.21 | C23: Neural Network | D23: Tested | E23: 84.815157 | F23: 1643 | G23: 85.175485 | H23: 283 | I23: Bilayered Neural Network | J23: 15.184843 | K23: 67.169696 | L23: 84.815157 | M23: 81.07085 | N23: 56.970527 | O23: 84.815157 | P23: 84.815157 | Q23: 58.450016 | R23: 84.815157 | S23: 81.685845 | T23: 14.824515 | U23: 68.758196 | V23: 85.175485 | W23: 81.5654 | X23: 57.00455 | Y23: 85.175485 | Z23: 85.175485 | AA23: 58.550339 | AB23: 85.175485 | AC23: 81.886496 | AD23: 182289.91 | AE23: 41.586708 | AF23: 9856 | AG23: 6878 | AH23: Number of fully connected layers: 2; First layer size: 10; Second layer size: 10; Activation: ReLU; Iteration limit: 1000; Regularization strength (Lambda): 0; Standardize data: Yes | AI23: 46305 | AJ23: None | AK23: Disabled | AL23: Default | AM23: Not applicable
A24: 0 | B24: 2.22 | C24: Neural Network | D24: Tested | E24: 84.399261 | F24: 1688 | G24: 85.437402 | H24: 278 | I24: Trilayered Neural Network | J24: 15.600739 | K24: 65.380325 | L24: 84.399261 | M24: 80.466774 | N24: 56.572651 | O24: 84.399261 | P24: 84.399261 | Q24: 57.871062 | R24: 84.399261 | S24: 81.340454 | T24: 14.562598 | U24: 70.075224 | V24: 85.437402 | W24: 82.477801 | X24: 59.628277 | Y24: 85.437402 | Z24: 85.437402 | AA24: 61.855126 | AB24: 85.437402 | AC24: 82.923635 | AD24: 428107.94 | AE24: 58.458947 | AF24: 11628 | AG24: 8126 | AH24: Number of fully connected layers: 3; First layer size: 10; Second layer size: 10; Third layer size: 10; Activation: ReLU; Iteration limit: 1000; Regularization strength (Lambda): 0; Standardize data: Yes | AI24: 46305 | AJ24: None | AK24: Disabled | AL24: Default | AM24: Not applicable
A25: 0 | B25: 2.23 | C25: Kernel | D25: Tested | E25: 85.101664 | F25: 1612 | G25: 85.123101 | H25: 284 | I25: SVM Kernel | J25: 14.898336 | K25: NaN | L25: 85.101664 | M25: NaN | N25: 50 | O25: 85.101664 | P25: 85.101664 | Q25: 45.975634 | R25: 85.101664 | S25: 78.252059 | T25: 14.876899 | U25: NaN | V25: 85.123101 | W25: NaN | X25: 50 | Y25: 85.123101 | Z25: 85.123101 | AA25: 45.98189 | AB25: 85.123101 | AC25: 78.282422 | AD25: 98702.815 | AE25: 38.379809 | AF25: 13438 | AG25: 14120 | AH25: Learner: SVM; Number of expansion dimensions: Auto; Regularization strength (Lambda): Auto; Kernel scale: Auto; Multiclass coding: One-vs-One; Standardize data: Yes; Iteration limit: 1000 | AI25: 46305 | AJ25: None | AK25: Disabled | AL25: Default | AM25: Not applicable
A26: 0 | B26: 2.24 | C26: Kernel | D26: Tested | E26: 85.138632 | F26: 1608 | G26: 84.965951 | H26: 287 | I26: Logistic Regression Kernel | J26: 14.861368 | K26: 68.969633 | L26: 85.138632 | M26: 80.486861 | N26: 51.0708 | O26: 85.138632 | P26: 85.138632 | Q26: 48.39596 | R26: 85.138632 | S26: 78.965219 | T26: 15.034049 | U26: 64.145732 | V26: 84.965951 | W26: 79.100158 | X26: 51.215276 | Y26: 84.965951 | Z26: 84.965951 | AA26: 48.865992 | AB26: 84.965951 | AC26: 79.046818 | AD26: 109432.21 | AE26: 37.844614 | AF26: 13472 | AG26: 14120 | AH26: Learner: Logistic Regression; Number of expansion dimensions: Auto; Regularization strength (Lambda): Auto; Kernel scale: Auto; Multiclass coding: One-vs-One; Standardize data: Yes; Iteration limit: 1000 | AI26: 46305 | AJ26: None | AK26: Disabled | AL26: Default | AM26: Not applicable
A27: 0 | B27: 2.3 | C27: Tree | D27: Tested | E27: 85.369686 | F27: 1583 | G27: 85.280251 | H27: 281 | I27: Coarse Tree | J27: 14.630314 | K27: 80.889668 | L27: 85.369686 | M27: 84.067092 | N27: 51.232139 | O27: 85.369686 | P27: 85.369686 | Q27: 48.556646 | R27: 85.369686 | S27: 79.107487 | T27: 14.719749 | U27: 92.628541 | V27: 85.280251 | W27: 87.450372 | X27: 50.528169 | Y27: 85.280251 | Z27: 85.280251 | AA27: 47.066253 | AB27: 85.280251 | AC27: 78.659947 | AD27: 811459.43 | AE27: 1.351553 | AF27: 5899 | AG27: 3722 | AH27: Maximum number of splits: 4; Split criterion: Gini's diversity index; Surrogate decision splits: Off | AI27: 46305 | AJ27: None | AK27: Disabled | AL27: Default | AM27: Not applicable
A28: 0 | B28: 2.4 | C28: Binary GLM Logistic Regression | D28: Tested | E28: 85.637708 | F28: 1554 | G28: 86.01362 | H28: 267 | I28: Binary GLM Logistic Regression | J28: 14.362292 | K28: 72.247718 | L28: 85.637708 | M28: 82.334029 | N28: 55.76504 | O28: 85.637708 | P28: 85.637708 | Q28: 56.805389 | R28: 85.637708 | S28: 81.580309 | T28: 13.98638 | U28: 74.610507 | V28: 86.01362 | W28: 83.244936 | X28: 56.770423 | Y28: 86.01362 | Z28: 86.01362 | AA28: 58.328489 | AB28: 86.01362 | AC28: 82.188232 | AD28: 626302.38 | AE28: 2.496475 | AF28: 2486822 | AG28: 6001 | AH28: None | AI28: 46305 | AJ28: None | AK28: Disabled | AL28: Default | AM28: Not applicable
A29: 0 | B29: 2.5 | C29: Efficient Logistic Regression | D29: Tested | E29: 85.101664 | F29: 1612 | G29: 85.123101 | H29: 284 | I29: Efficient Logistic Regression | J29: 14.898336 | K29: NaN | L29: 85.101664 | M29: NaN | N29: 50 | O29: 85.101664 | P29: 85.101664 | Q29: 45.975634 | R29: 85.101664 | S29: 78.252059 | T29: 14.876899 | U29: NaN | V29: 85.123101 | W29: NaN | X29: 50 | Y29: 85.123101 | Z29: 85.123101 | AA29: 45.98189 | AB29: 85.123101 | AC29: 78.282422 | AD29: 758712.57 | AE29: 0.690451 | AF29: 11632 | AG29: 3496 | AH29: Learner: Logistic regression; Solver: Auto; Regularization: Auto; Regularization strength (Lambda): Auto; Relative coefficient tolerance (Beta tolerance): 0.0001; Multiclass coding: One-vs-One | AI29: 46305 | AJ29: None | AK29: Disabled | AL29: Default | AM29: Not applicable
A30: 0 | B30: 2.6 | C30: Efficient Linear SVM | D30: Tested | E30: 85.101664 | F30: 1612 | G30: 85.123101 | H30: 284 | I30: Efficient Linear SVM | J30: 14.898336 | K30: NaN | L30: 85.101664 | M30: NaN | N30: 50 | O30: 85.101664 | P30: 85.101664 | Q30: 45.975634 | R30: 85.101664 | S30: 78.252059 | T30: 14.876899 | U30: NaN | V30: 85.123101 | W30: NaN | X30: 50 | Y30: 85.123101 | Z30: 85.123101 | AA30: 45.98189 | AB30: 85.123101 | AC30: 78.282422 | AD30: 734854.66 | AE30: 1.359405 | AF30: 11590 | AG30: 3496 | AH30: Learner: SVM; Solver: Auto; Regularization: Auto; Regularization strength (Lambda): Auto; Relative coefficient tolerance (Beta tolerance): 0.0001; Multiclass coding: One-vs-One | AI30: 46305 | AJ30: None | AK30: Disabled | AL30: Default | AM30: Not applicable
A31: 0 | B31: 2.7 | C31: Naive Bayes | D31: Tested | E31: 83.696858 | F31: 1764 | G31: 83.603981 | H31: 313 | I31: Gaussian Naive Bayes | J31: 16.303142 | K31: 65.162565 | L31: 83.696858 | M31: 81.131994 | N31: 60.049237 | O31: 83.696858 | P31: 83.696858 | Q31: 61.622846 | R31: 83.696858 | S31: 82.055967 | T31: 16.396019 | U31: 65.357742 | V31: 83.603981 | W31: 81.423538 | X31: 61.021235 | Y31: 83.603981 | Z31: 83.603981 | AA31: 62.506549 | AB31: 83.603981 | AC31: 82.263292 | AD31: 514503.09 | AE31: 1.118431 | AF31: 8976 | AG31: 7327 | AH31: Distribution name for numeric predictors: Gaussian; Distribution name for categorical predictors: MVMN | AI31: 46305 | AJ31: None | AK31: Disabled | AL31: Default | AM31: Not applicable
A32: 0 | B32: 2.8 | C32: Naive Bayes | D32: Tested | E32: 84.09427 | F32: 1721 | G32: 83.865898 | H32: 308 | I32: Kernel Naive Bayes | J32: 15.90573 | K32: 65.584865 | L32: 84.09427 | M32: 81.0114 | N32: 58.926602 | O32: 84.09427 | P32: 84.09427 | Q32: 60.603664 | R32: 84.09427 | S32: 81.960294 | T32: 16.134102 | U32: 65.340117 | V32: 83.865898 | W32: 81.133552 | X32: 59.72221 | Y32: 83.865898 | Z32: 83.865898 | AA32: 61.35404 | AB32: 83.865898 | AC32: 82.073602 | AD32: 868.32313 | AE32: 48.818487 | AF32: 3155968 | AG32: 1565693 | AH32: Distribution name for numeric predictors: Kernel; Distribution name for categorical predictors: MVMN; Kernel type: Gaussian; Support: Unbounded; Standardize data: Yes | AI32: 46305 | AJ32: None | AK32: Disabled | AL32: Default | AM32: Not applicable
A33: 0 | B33: 2.9 | C33: SVM | D33: Tested | E33: 85.101664 | F33: 1612 | G33: 85.123101 | H33: 284 | I33: Linear SVM | J33: 14.898336 | K33: NaN | L33: 85.101664 | M33: NaN | N33: 50 | O33: 85.101664 | P33: 85.101664 | Q33: 45.975634 | R33: 85.101664 | S33: 78.252059 | T33: 14.876899 | U33: NaN | V33: 85.123101 | W33: NaN | X33: 50 | Y33: 85.123101 | Z33: 85.123101 | AA33: 45.98189 | AB33: 85.123101 | AC33: 78.282422 | AD33: 121267.82 | AE33: 6.761915 | AF33: 401619 | AG33: 399530 | AH33: Kernel function: Linear; Kernel scale: Automatic; Box constraint level: 1; Multiclass coding: One-vs-One; Standardize data: Yes | AI33: 46305 | AJ33: None | AK33: Disabled | AL33: Default | AM33: Not applicable

Sheet V3
A1: Session: untitled
A2: Training Data: Excel_MultiModal_Dataset1 Observations: 10820
A3: Predictors: 10 Predictor Names: body_temperature, sleep_quality, muscle_activity, step_count, ground_reaction_force, altitude, training_load, fatigue_index, sport_type, age
A4: Response Name: injury_occurred Response Classes: 2 Response Class Names: 0, 1
A5: Validation: 5-fold cross-validation
A6: Test Data: Excel_MultiModal_Dataset1 Observations: 1909
A9: Favorite | B9: Model Number | C9: Model Type | D9: Status | E9: Accuracy % (Validation) | F9: Total Cost (Validation) | G9: Accuracy % (Test) | H9: Total Cost (Test) | I9: Preset | J9: Error Rate % (Validation) | K9: Macro Precision % (Validation) | L9: Micro Precision % (Validation) | M9: Weighted Precision % (Validation) | N9: Macro Recall % (Validation) | O9: Micro Recall % (Validation) | P9: Weighted Recall % (Validation) | Q9: Macro F1 Score % (Validation) | R9: Micro F1 Score % (Validation) | S9: Weighted F1 Score % (Validation) | T9: Error Rate % (Test) | U9: Macro Precision % (Test) | V9: Micro Precision % (Test) | W9: Weighted Precision % (Test) | X9: Macro Recall % (Test) | Y9: Micro Recall % (Test) | Z9: Weighted Recall % (Test) | AA9: Macro F1 Score % (Test) | AB9: Micro F1 Score % (Test) | AC9: Weighted F1 Score % (Test) | AD9: Prediction Speed (obs/sec) | AE9: Training Time (sec) | AF9: Compact Model Size (bytes) | AG9: Coder Model Size (bytes) | AH9: Hyperparameters | AI9: Selected Features | AJ9: Feature Ranking Algorithm | AK9: PCA | AL9: Costs | AM9: Optimizer Options
A10: 0 | B10: 2.1 | C10: Tree | D10: Tested | E10: 84.852126 | F10: 1639 | G10: 84.442116 | H10: 297 | I10: Fine Tree | J10: 15.147874 | K10: 67.713669 | L10: 84.852126 | M10: 81.548985 | N10: 58.503192 | O10: 84.852126 | P10: 84.852126 | Q10: 60.359811 | R10: 84.852126 | S10: 82.240188 | T10: 15.557884 | U10: 65.494886 | V10: 84.442116 | W10: 80.409843 | X10: 56.284461 | Y10: 84.442116 | Z10: 84.442116 | AA10: 57.494484 | AB10: 84.442116 | AC10: 81.233221 | AD10: 725784.81 | AE10: 3.573249 | AF10: 31699 | AG10: 21442 | AH10: Maximum number of splits: 100; Split criterion: Gini's diversity index; Surrogate decision splits: Off | AI10: 46305 | AJ10: None | AK10: Disabled | AL10: Default | AM10: Not applicable
A11: 0 | B11: 2.1 | C11: SVM | D11: Tested | E11: 85.110906 | F11: 1611 | G11: 85.070718 | H11: 285 | I11: Quadratic SVM | J11: 14.889094 | K11: NaN | L11: 85.110906 | M11: NaN | N11: 50 | O11: 85.110906 | P11: 85.110906 | Q11: 45.978331 | R11: 85.110906 | S11: 78.265149 | T11: 14.929282 | U11: NaN | V11: 85.070718 | W11: NaN | X11: 50 | Y11: 85.070718 | Z11: 85.070718 | AA11: 45.966601 | AB11: 85.070718 | AC11: 78.208234 | AD11: 11833.051 | AE11: 61.723031 | AF11: 505443 | AG11: 503450 | AH11: Kernel function: Quadratic; Kernel scale: Automatic; Box constraint level: 1; Multiclass coding: One-vs-One; Standardize data: Yes | AI11: 46305 | AJ11: None | AK11: Disabled | AL11: Default | AM11: Not applicable
A12: 0 | B12: 2.11 | C12: SVM | D12: Tested | E12: 85.582255 | F12: 1560 | G12: 85.385018 | H12: 279 | I12: Cubic SVM | J12: 14.417745 | K12: 75.170598 | L12: 85.582255 | M12: 82.729147 | N12: 53.196118 | O12: 85.582255 | P12: 85.582255 | Q12: 52.446764 | R12: 85.582255 | S12: 80.321372 | T12: 14.614982 | U12: 73.626374 | V12: 85.385018 | W12: 82.105009 | X12: 52.499136 | Y12: 85.385018 | Z12: 85.385018 | AA12: 51.166936 | AB12: 85.385018 | AC12: 79.839034 | AD12: 303166.15 | AE12: 510.21194 | AF12: 418683 | AG12: 416690 | AH12: Kernel function: Cubic; Kernel scale: Automatic; Box constraint level: 1; Multiclass coding: One-vs-One; Standardize data: Yes | AI12: 46305 | AJ12: None | AK12: Disabled | AL12: Default | AM12: Not applicable
A13: 0 | B13: 2.12 | C13: SVM | D13: Tested | E13: 85.110906 | F13: 1611 | G13: 85.070718 | H13: 285 | I13: Fine Gaussian SVM | J13: 14.889094 | K13: NaN | L13: 85.110906 | M13: NaN | N13: 50 | O13: 85.110906 | P13: 85.110906 | Q13: 45.978331 | R13: 85.110906 | S13: 78.265149 | T13: 14.929282 | U13: NaN | V13: 85.070718 | W13: NaN | X13: 50 | Y13: 85.070718 | Z13: 85.070718 | AA13: 45.966601 | AB13: 85.070718 | AC13: 78.208234 | AD13: 4824.202 | AE13: 40.799668 | AF13: 1299119 | AG13: 1297130 | AH13: Kernel function: Gaussian; Kernel scale: 0.79; Box constraint level: 1; Multiclass coding: One-vs-One; Standardize data: Yes | AI13: 46305 | AJ13: None | AK13: Disabled | AL13: Default | AM13: Not applicable
A14: 0 | B14: 2.13 | C14: SVM | D14: Tested | E14: 85.462107 | F14: 1573 | G14: 85.175485 | H14: 283 | I14: Medium Gaussian SVM | J14: 14.537893 | K14: 76.02411 | L14: 85.462107 | M14: 82.796862 | N14: 52.178071 | O14: 85.462107 | P14: 85.462107 | Q14: 50.508918 | R14: 85.462107 | S14: 79.715377 | T14: 14.824515 | U14: 71.262721 | V14: 85.175485 | W14: 81.166597 | X14: 51.21878 | Y14: 85.175485 | Z14: 85.175485 | AA14: 48.654557 | AB14: 85.175485 | AC14: 79.028173 | AD14: 7255.2882 | AE14: 33.59726 | AF14: 485399 | AG14: 483410 | AH14: Kernel function: Gaussian; Kernel scale: 3.2; Box constraint level: 1; Multiclass coding: One-vs-One; Standardize data: Yes | AI14: 46305 | AJ14: None | AK14: Disabled | AL14: Default | AM14: Not applicable
A15: 0 | B15: 2.14 | C15: SVM | D15: Tested | E15: 85.110906 | F15: 1611 | G15: 85.070718 | H15: 285 | I15: Coarse Gaussian SVM | J15: 14.889094 | K15: NaN | L15: 85.110906 | M15: NaN | N15: 50 | O15: 85.110906 | P15: 85.110906 | Q15: 45.978331 | R15: 85.110906 | S15: 78.265149 | T15: 14.929282 | U15: NaN | V15: 85.070718 | W15: NaN | X15: 50 | Y15: 85.070718 | Z15: 85.070718 | AA15: 45.966601 | AB15: 85.070718 | AC15: 78.208234 | AD15: 9107.3991 | AE15: 34.862489 | AF15: 447359 | AG15: 445370 | AH15: Kernel function: Gaussian; Kernel scale: 13; Box constraint level: 1; Multiclass coding: One-vs-One; Standardize data: Yes | AI15: 46305 | AJ15: None | AK15: Disabled | AL15: Default | AM15: Not applicable
A16: 0 | B16: 2.15 | C16: Ensemble | D16: Tested | E16: 86.219963 | F16: 1491 | G16: 86.066003 | H16: 266 | I16: Boosted Trees | J16: 13.780037 | K16: 76.338745 | L16: 86.219963 | M16: 83.804685 | N16: 57.078932 | O16: 86.219963 | P16: 86.219963 | Q16: 58.799607 | R16: 86.219963 | S16: 82.402175 | T16: 13.933997 | U16: 75.930798 | V16: 86.066003 | W16: 83.54215 | X16: 56.515643 | Y16: 86.066003 | Z16: 86.066003 | AA16: 57.948756 | AB16: 86.066003 | AC16: 82.067266 | AD16: 31165.031 | AE16: 14.622953 | AF16: 311860 | AG16: 140537 | AH16: Ensemble method: AdaBoost; Learner type: Decision tree; Maximum number of splits: 20; Number of learners: 30; Learning rate: 0.1; Number of predictors to sample: Select All | AI16: 46305 | AJ16: None | AK16: Disabled | AL16: Default | AM16: Not applicable
A17: 0 | B17: 2.16 | C17: Ensemble | D17: Tested | E17: 85.406654 | F17: 1579 | G17: 85.804086 | H17: 271 | I17: Bagged Trees | J17: 14.593346 | K17: 69.990822 | L17: 85.406654 | M17: 82.22239 | N17: 58.547282 | O17: 85.406654 | P17: 85.406654 | Q17: 60.575857 | R17: 85.406654 | S17: 82.54679 | T17: 14.195914 | U17: 72.420198 | V17: 85.804086 | W17: 82.809199 | X17: 58.097507 | Y17: 85.804086 | Z17: 85.804086 | AA17: 60.120547 | AB17: 85.804086 | AC17: 82.568496 | AD17: 19349.589 | AE17: 29.757966 | AF17: 6722812 | AG17: 4863449 | AH17: Ensemble method: Bag; Learner type: Decision tree; Maximum number of splits: 10819; Number of learners: 30; Number of predictors to sample: Select All | AI17: 46305 | AJ17: None | AK17: Disabled | AL17: Default | AM17: Not applicable
A18: 0 | B18: 2.17 | C18: Ensemble | D18: Tested | E18: 71.238447 | F18: 3112 | G18: 75.065479 | H18: 476 | I18: RUSBoosted Trees | J18: 28.761553 | K18: 62.1163 | L18: 71.238447 | M18: 84.316836 | N18: 71.91316 | O18: 71.238447 | P18: 71.238447 | Q18: 61.885021 | R18: 71.238447 | S18: 75.143852 | T18: 24.934521 | U18: 63.695891 | V18: 75.065479 | W18: 84.636577 | X18: 73.049542 | Y18: 75.065479 | Z18: 75.065479 | AA18: 64.741315 | AB18: 75.065479 | AC18: 78.123751 | AD18: 30990.7 | AE18: 12.600015 | AF18: 294824 | AG18: 115517 | AH18: Ensemble method: RUSBoost; Learner type: Decision tree; Maximum number of splits: 20; Number of learners: 30; Learning rate: 0.1; Number of predictors to sample: Select All | AI18: 46305 | AJ18: None | AK18: Disabled | AL18: Default | AM18: Not applicable
A19: 0 | B19: 2.18 | C19: Neural Network | D19: Tested | E19: 85.591497 | F19: 1559 | G19: 85.123101 | H19: 284 | I19: Narrow Neural Network | J19: 14.408503 | K19: 71.331512 | L19: 85.591497 | M19: 82.253626 | N19: 56.709728 | O19: 85.591497 | P19: 85.591497 | Q19: 58.197248 | R19: 85.591497 | S19: 81.960406 | T19: 14.876899 | U19: 68.578446 | V19: 85.123101 | W19: 81.11568 | X19: 55.238203 | Y19: 85.123101 | Z19: 85.123101 | AA19: 56.010684 | AB19: 85.123101 | AC19: 81.111474 | AD19: 239274.66 | AE19: 38.713508 | AF19: 8084 | AG19: 5630 | AH19: Number of fully connected layers: 1; First layer size: 10; Activation: ReLU; Iteration limit: 1000; Regularization strength (Lambda): 0; Standardize data: Yes | AI19: 46305 | AJ19: None | AK19: Disabled | AL19: Default | AM19: Not applicable
A20: 0 | B20: 2.19 | C20: Neural Network | D20: Tested | E20: 84.916821 | F20: 1632 | G20: 84.442116 | H20: 297 | I20: Medium Neural Network | J20: 15.083179 | K20: 67.857845 | L20: 84.916821 | M20: 81.510057 | N20: 58.105877 | O20: 84.916821 | P20: 84.916821 | Q20: 59.902525 | R20: 84.916821 | S20: 82.142008 | T20: 15.557884 | U20: 65.417982 | V20: 84.442116 | W20: 80.358343 | X20: 56.139811 | Y20: 84.442116 | Z20: 84.442116 | AA20: 57.299723 | AB20: 84.442116 | AC20: 81.178609 | AD20: 179796.94 | AE20: 59.582749 | AF20: 10004 | AG20: 7550 | AH20: Number of fully connected layers: 1; First layer size: 25; Activation: ReLU; Iteration limit: 1000; Regularization strength (Lambda): 0; Standardize data: Yes | AI20: 46305 | AJ20: None | AK20: Disabled | AL20: Default | AM20: Not applicable
A21: 0 | B21: 2.2 | C21: Tree | D21: Tested | E21: 85.813309 | F21: 1535 | G21: 85.908853 | H21: 269 | I21: Medium Tree | J21: 14.186691 | K21: 73.26585 | L21: 85.813309 | M21: 82.761427 | N21: 56.379106 | O21: 85.813309 | P21: 85.813309 | Q21: 57.736138 | R21: 85.813309 | S21: 81.925994 | T21: 14.091147 | U21: 73.419373 | V21: 85.908853 | W21: 83.002991 | X21: 57.580481 | Y21: 85.908853 | Z21: 85.908853 | AA21: 59.454078 | AB21: 85.908853 | AC21: 82.426155 | AD21: 783660.46 | AE21: 1.455887 | AF21: 10199 | AG21: 5230 | AH21: Maximum number of splits: 20; Split criterion: Gini's diversity index; Surrogate decision splits: Off | AI21: 46305 | AJ21: None | AK21: Disabled | AL21: Default | AM21: Not applicable
A22: 0 | B22: 2.2 | C22: Neural Network | D22: Tested | E22: 79.436229 | F22: 2225 | G22: 79.622839 | H22: 389 | I22: Wide Neural Network | J22: 20.563771 | K22: 58.447422 | L22: 79.436229 | M22: 78.809138 | N22: 57.933452 | O22: 79.436229 | P22: 79.436229 | Q22: 58.168534 | R22: 79.436229 | S22: 79.113699 | T22: 20.377161 | U22: 57.665768 | V22: 79.622839 | W22: 78.239959 | X22: 56.634258 | Y22: 79.622839 | Z22: 79.622839 | AA22: 57.045913 | AB22: 79.622839 | AC22: 78.888763 | AD22: 419055 | AE22: 89.527807 | AF22: 19604 | AG22: 17150 | AH22: Number of fully connected layers: 1; First layer size: 100; Activation: ReLU; Iteration limit: 1000; Regularization strength (Lambda): 0; Standardize data: Yes | AI22: 46305 | AJ22: None | AK22: Disabled | AL22: Default | AM22: Not applicable
A23: 0 | B23: 2.21 | C23: Neural Network | D23: Tested | E23: 84.61183 | F23: 1665 | G23: 85.227868 | H23: 282 | I23: Bilayered Neural Network | J23: 15.38817 | K23: 65.971352 | L23: 84.61183 | M23: 80.572419 | N23: 56.185418 | O23: 84.61183 | P23: 84.61183 | Q23: 57.377587 | R23: 84.61183 | S23: 81.302408 | T23: 14.772132 | U23: 69.281121 | V23: 85.227868 | W23: 81.673863 | X23: 57.035585 | Y23: 85.227868 | Z23: 85.227868 | AA23: 58.599575 | AB23: 85.227868 | AC23: 81.888461 | AD23: 293383.95 | AE23: 59.123285 | AF23: 9856 | AG23: 6878 | AH23: Number of fully connected layers: 2; First layer size: 10; Second layer size: 10; Activation: ReLU; Iteration limit: 1000; Regularization strength (Lambda): 0; Standardize data: Yes | AI23: 46305 | AJ23: None | AK23: Disabled | AL23: Default | AM23: Not applicable
A24: 0 | B24: 2.22 | C24: Neural Network | D24: Tested | E24: 84.713494 | F24: 1654 | G24: 83.603981 | H24: 313 | I24: Trilayered Neural Network | J24: 15.286506 | K24: 66.684454 | L24: 84.713494 | M24: 80.921062 | N24: 56.885321 | O24: 84.713494 | P24: 84.713494 | Q24: 58.322881 | R24: 84.713494 | S24: 81.6116 | T24: 16.396019 | U24: 61.988731 | V24: 83.603981 | W24: 79.165479 | X24: 55.213249 | Y24: 83.603981 | Z24: 83.603981 | AA24: 56.004659 | AB24: 83.603981 | AC24: 80.446122 | AD24: 443551.69 | AE24: 58.483928 | AF24: 11628 | AG24: 8126 | AH24: Number of fully connected layers: 3; First layer size: 10; Second layer size: 10; Third layer size: 10; Activation: ReLU; Iteration limit: 1000; Regularization strength (Lambda): 0; Standardize data: Yes | AI24: 46305 | AJ24: None | AK24: Disabled | AL24: Default | AM24: Not applicable
A25: 0 | B25: 2.23 | C25: Kernel | D25: Tested | E25: 85.110906 | F25: 1611 | G25: 85.070718 | H25: 285 | I25: SVM Kernel | J25: 14.889094 | K25: NaN | L25: 85.110906 | M25: NaN | N25: 50 | O25: 85.110906 | P25: 85.110906 | Q25: 45.978331 | R25: 85.110906 | S25: 78.265149 | T25: 14.929282 | U25: NaN | V25: 85.070718 | W25: NaN | X25: 50 | Y25: 85.070718 | Z25: 85.070718 | AA25: 45.966601 | AB25: 85.070718 | AC25: 78.208234 | AD25: 140193.58 | AE25: 36.673257 | AF25: 13438 | AG25: 14120 | AH25: Learner: SVM; Number of expansion dimensions: Auto; Regularization strength (Lambda): Auto; Kernel scale: Auto; Multiclass coding: One-vs-One; Standardize data: Yes; Iteration limit: 1000 | AI25: 46305 | AJ25: None | AK25: Disabled | AL25: Default | AM25: Not applicable
A26: 0 | B26: 2.24 | C26: Kernel | D26: Tested | E26: 84.963031 | F26: 1627 | G26: 84.861184 | H26: 289 | I26: Logistic Regression Kernel | J26: 15.036969 | K26: 63.320891 | L26: 84.963031 | M26: 78.781307 | N26: 50.8862 | O26: 84.963031 | P26: 84.963031 | Q26: 48.151003 | R26: 84.963031 | S26: 78.829712 | T26: 15.138816 | U26: 63.14135 | V26: 84.861184 | W26: 78.735375 | X26: 51.178701 | Y26: 84.861184 | Z26: 84.861184 | AA26: 48.81596 | AB26: 84.861184 | AC26: 78.943647 | AD26: 103211.77 | AE26: 35.753304 | AF26: 13480 | AG26: 14120 | AH26: Learner: Logistic Regression; Number of expansion dimensions: Auto; Regularization strength (Lambda): Auto; Kernel scale: Auto; Multiclass coding: One-vs-One; Standardize data: Yes; Iteration limit: 1000 | AI26: 46305 | AJ26: None | AK26: Disabled | AL26: Default | AM26: Not applicable
A27: 0 | B27: 2.3 | C27: Tree | D27: Tested | E27: 85.249538 | F27: 1596 | G27: 85.437402 | H27: 278 | I27: Coarse Tree | J27: 14.750462 | K27: 89.676615 | L27: 85.249538 | M27: 86.558042 | N27: 50.491157 | O27: 85.249538 | P27: 85.249538 | Q27: 46.995194 | R27: 85.249538 | S27: 78.615788 | T27: 14.562598 | U27: 92.691903 | V27: 85.437402 | W27: 87.565899 | X27: 51.22807 | Y27: 85.437402 | Z27: 85.437402 | AA27: 48.455116 | AB27: 85.437402 | AC27: 79.079285 | AD27: 752329.3 | AE27: 0.910672 | AF27: 5899 | AG27: 3722 | AH27: Maximum number of splits: 4; Split criterion: Gini's diversity index; Surrogate decision splits: Off | AI27: 46305 | AJ27: None | AK27: Disabled | AL27: Default | AM27: Not applicable
A28: 0 | B28: 2.4 | C28: Binary GLM Logistic Regression | D28: Tested | E28: 85.739372 | F28: 1543 | G28: 85.646936 | H28: 274 | I28: Binary GLM Logistic Regression | J28: 14.260628 | K28: 72.733855 | L28: 85.739372 | M28: 82.576077 | N28: 56.233242 | O28: 85.739372 | P28: 85.739372 | Q28: 57.51587 | R28: 85.739372 | S28: 81.831798 | T28: 14.353064 | U28: 72.426953 | V28: 85.646936 | W28: 82.399661 | X28: 55.980036 | Y28: 85.646936 | Z28: 85.646936 | AA28: 57.126862 | AB28: 85.646936 | AC28: 81.653759 | AD28: 576574.66 | AE28: 2.455078 | AF28: 2486822 | AG28: 6001 | AH28: None | AI28: 46305 | AJ28: None | AK28: Disabled | AL28: Default | AM28: Not applicable
A29: 0 | B29: 2.5 | C29: Efficient Logistic Regression | D29: Tested | E29: 85.110906 | F29: 1611 | G29: 85.070718 | H29: 285 | I29: Efficient Logistic Regression | J29: 14.889094 | K29: NaN | L29: 85.110906 | M29: NaN | N29: 50 | O29: 85.110906 | P29: 85.110906 | Q29: 45.978331 | R29: 85.110906 | S29: 78.265149 | T29: 14.929282 | U29: NaN | V29: 85.070718 | W29: NaN | X29: 50 | Y29: 85.070718 | Z29: 85.070718 | AA29: 45.966601 | AB29: 85.070718 | AC29: 78.208234 | AD29: 745127.75 | AE29: 1.03134 | AF29: 11632 | AG29: 3496 | AH29: Learner: Logistic regression; Solver: Auto; Regularization: Auto; Regularization strength (Lambda): Auto; Relative coefficient tolerance (Beta tolerance): 0.0001; Multiclass coding: One-vs-One | AI29: 46305 | AJ29: None | AK29: Disabled | AL29: Default | AM29: Not applicable
A30: 0 | B30: 2.6 | C30: Efficient Linear SVM | D30: Tested | E30: 85.110906 | F30: 1611 | G30: 85.070718 | H30: 285 | I30: Efficient Linear SVM | J30: 14.889094 | K30: NaN | L30: 85.110906 | M30: NaN | N30: 50 | O30: 85.110906 | P30: 85.110906 | Q30: 45.978331 | R30: 85.110906 | S30: 78.265149 | T30: 14.929282 | U30: NaN | V30: 85.070718 | W30: NaN | X30: 50 | Y30: 85.070718 | Z30: 85.070718 | AA30: 45.966601 | AB30: 85.070718 | AC30: 78.208234 | AD30: 720516.75 | AE30: 0.522075 | AF30: 11590 | AG30: 3496 | AH30: Learner: SVM; Solver: Auto; Regularization: Auto; Regularization strength (Lambda): Auto; Relative coefficient tolerance (Beta tolerance): 0.0001; Multiclass coding: One-vs-One | AI30: 46305 | AJ30: None | AK30: Disabled | AL30: Default | AM30: Not applicable
A31: 0 | B31: 2.7 | C31: Naive Bayes | D31: Tested | E31: 83.752311 | F31: 1758 | G31: 83.918282 | H31: 307 | I31: Gaussian Naive Bayes | J31: 16.247689 | K31: 65.421098 | L31: 83.752311 | M31: 81.295335 | N31: 60.4178 | O31: 83.752311 | P31: 83.752311 | Q31: 62.003846 | R31: 83.752311 | S31: 82.190119 | T31: 16.081718 | U31: 65.120907 | V31: 83.918282 | W31: 80.802954 | X31: 58.724937 | Y31: 83.918282 | Z31: 83.918282 | AA31: 60.334065 | AB31: 83.918282 | AC31: 81.787371 | AD31: 507409.49 | AE31: 0.927775 | AF31: 8976 | AG31: 7327 | AH31: Distribution name for numeric predictors: Gaussian; Distribution name for categorical predictors: MVMN | AI31: 46305 | AJ31: None | AK31: Disabled | AL31: Default | AM31: Not applicable
A32: 0 | B32: 2.8 | C32: Naive Bayes | D32: Tested | E32: 84.038817 | F32: 1727 | G32: 83.918282 | H32: 307 | I32: Kernel Naive Bayes | J32: 15.961183 | K32: 65.54494 | L32: 84.038817 | M32: 81.068192 | N32: 59.203328 | O32: 84.038817 | P32: 84.038817 | Q32: 60.880466 | R32: 84.038817 | S32: 82.01646 | T32: 16.081718 | U32: 64.361752 | V32: 83.918282 | W32: 80.280411 | X32: 57.278433 | Y32: 83.918282 | Z32: 83.918282 | AA32: 58.67607 | AB32: 83.918282 | AC32: 81.329771 | AD32: 1042.2601 | AE32: 45.759575 | AF32: 3155968 | AG32: 1565693 | AH32: Distribution name for numeric predictors: Kernel; Distribution name for categorical predictors: MVMN; Kernel type: Gaussian; Support: Unbounded; Standardize data: Yes | AI32: 46305 | AJ32: None | AK32: Disabled | AL32: Default | AM32: Not applicable
A33: 0 | B33: 2.9 | C33: SVM | D33: Tested | E33: 85.110906 | F33: 1611 | G33: 85.070718 | H33: 285 | I33: Linear SVM | J33: 14.889094 | K33: NaN | L33: 85.110906 | M33: NaN | N33: 50 | O33: 85.110906 | P33: 85.110906 | Q33: 45.978331 | R33: 85.110906 | S33: 78.265149 | T33: 14.929282 | U33: NaN | V33: 85.070718 | W33: NaN | X33: 50 | Y33: 85.070718 | Z33: 85.070718 | AA33: 45.966601 | AB33: 85.070718 | AC33: 78.208234 | AD33: 31426.447 | AE33: 8.949554 | AF33: 401619 | AG33: 399530 | AH33: Kernel function: Linear; Kernel scale: Automatic; Box constraint level: 1; Multiclass coding: One-vs-One; Standardize data: Yes | AI33: 46305 | AJ33: None | AK33: Disabled | AL33: Default | AM33: Not applicable

Sheet V4
A1: Session: untitled
A2: Training Data: Excel_MultiModal_Dataset1 Observations: 10820
A3: Predictors: 10 Predictor Names: body_temperature, sleep_quality, muscle_activity, step_count, ground_reaction_force, altitude, training_load, fatigue_index, sport_type, age
A4: Response Name: injury_occurred Response Classes: 2 Response Class Names: 0, 1
A5: Validation: 5-fold cross-validation
A6: Test Data: Excel_MultiModal_Dataset1 Observations: 1909
